Workbook
Name Slicer_CVD_Risk_Level: #N/A

Sheet CVD Risk by Age Band
A1: 1️⃣ Create an age-band classification (25–35, 36–45, 46–55, 56–65, 66+) and calculate % of High Risk patients and Average CVD Risk Score per band. Which age group shows the highest risk concentration?
A3: Why this question is asked:
A4: Cardiovascular risk increases with age but not always uniformly.
A6: Business purpose:
A7: Helps hospitals design age-targeted screening and preventive strategies.
B9: Column Labels
B10: Average of CVD Risk Score | E10: Count of CVD Risk Level | H10: Total Average of CVD Risk Score | I10: Total Count of CVD Risk Level | J10: % Distribution Of High Risk Patients
A11: Age Band | B11: HIGH | C11: INTERMEDIARY | D11: LOW | E11: HIGH | F11: INTERMEDIARY | G11: LOW
A12: 25-34 | B12: 17.924467 | C12: 16.514105 | D12: 16.430091 | E12: 112 | F12: 108 | G12: 48 | H12: 17.089152 | I12: 268 | J12: =E12*100/I12 -> 41.791045
A13: 35-44 | B13: 17.865925 | C13: 16.123296 | D13: 15.83437 | E13: 153 | F13: 197 | G13: 51 | H13: 16.759097 | I13: 401 | J13: =E13*100/I13 -> 38.154613
A14: 45-54 | B14: 17.290869 | C14: 15.740337 | D14: 17.995824 | E14: 236 | F14: 108 | G14: 35 | H14: 16.91679 | I14: 379 | J14: =E14*100/I14 -> 62.269129
A15: 55-64 | B15: 17.760869 | C15: 15.690674 | D15: 18.049963 | E15: 145 | F15: 94 | G15: 32 | H15: 17.06347 | I15: 271 | J15: =E15*100/I15 -> 53.505535
A16: 65-74 | B16: 16.835031 | C16: 17.228481 | D16: 18.020333 | E16: 33 | F16: 28 | G16: 21 | H16: 17.278963 | I16: 82 | J16: =E16*100/I16 -> 40.243902
A17: 75-84 | B17: 17.988462 | C17: 17.111562 | D17: 17.878059 | E17: 14 | F17: 17 | G17: 19 | H17: 17.642652 | I17: 50 | J17: =E17*100/I17 -> 28
A18: Grand Total | B18: 17.608463 | C18: 16.139062 | D18: 17.105111 | E18: 693 | F18: 552 | G18: 206 | H18: 16.977021 | I18: 1451
A23: The 45–54 age band shows the highest risk concentration, with 62.27% of patients classified as High Risk. Although the 75–84 age group shows the highest average CVD risk score, the sample size is relatively small and should be interpreted cautiously. This suggests that middle-aged cohorts may represent the largest actionable risk segment for preventive intervention.

Sheet CVD Risk by Sex
A1: 2️⃣ Perform gender-based risk comparison: Average CVD Risk Score by Sex and % High Risk by Sex. Is risk significantly different between males and females?
A3: Why:
A4: Risk profiles differ biologically and behaviorally.
A6: Purpose:
A7: Enables gender-specific public health policies.
B12: Column Labels
B13: Average of CVD Risk Score | D13: Count of High Risk Patients | F13: Total Average of CVD Risk Score | G13: Total Count of High Risk Patients | H13: % OF High Risk Patients
A14: Gender | B14: High Risk Patients | C14: Not High Risk Patients | D14: High Risk Patients | E14: Not High Risk Patients
A15: F | B15: 17.514584 | C15: 16.369841 | D15: 379 | E15: 394 | F15: 16.935974 | G15: 773 | H15: =D15*100/G15 -> 49.029754
A16: M | B16: 17.716461 | C16: 16.362371 | D16: 349 | E16: 407 | F16: 16.986186 | G16: 756 | H16: =D16*100/G16 -> 46.164021
A17: Grand Total | B17: 17.611323 | C17: 16.366008 | D17: 728 | E17: 801 | F17: 16.960925 | G17: 1529 | H17: =D17*100/G17 -> 47.612819
A20: The overall average CVD Risk Score is nearly identical between males (16.99) and females (16.94), indicating minimal gender-based difference in risk severity. Females show a slightly higher proportion of High Risk patients (49.03%) compared to males (46.16%), but the gap is modest. This suggests that gender alone is not a dominant risk differentiator in this dataset, and prevention strategies should focus more on clinical and lifestyle factors.

Sheet Sex & Smoking Risk Profile
A1: 3️⃣ Create a cross-tab of Sex × Smoking Status × Risk Level. Which demographic segment is most vulnerable?
A3: Why:
A4: Risk is often amplified by lifestyle within demographic groups.
A6: Purpose:
A7: Improves targeted awareness campaigns.
A11: Total Patients | B11: Risk Level
A12: Gender | B12: HIGH | C12: INTERMEDIARY | D12: LOW | E12: Grand Total
A13: F | B13: 0.49118046 | C13: 0.37449118 | D13: 0.13432836 | E13: 1
A14: N | B14: 0.39548023 | C14: 0.46045198 | D14: 0.1440678 | E14: 1
A15: Y | B15: 0.57963446 | C15: 0.29503916 | D15: 0.12532637 | E15: 1
A16: M | B16: 0.4556962 | C16: 0.38959212 | D16: 0.15471167 | E16: 1
A17: N | B17: 0.33913043 | C17: 0.48695652 | D17: 0.17391304 | E17: 1
A18: Y | B18: 0.56557377 | C18: 0.29781421 | D18: 0.13661202 | E18: 1
A19: Grand Total | B19: 0.47375691 | C19: 0.38190608 | D19: 0.14433702 | E19: 1
A22: Smoking significantly increases cardiovascular risk across both genders. Female smokers show the highest vulnerability, with ~58% of patients classified as High Risk, followed closely by male smokers (~56.6%). Non-smokers in both genders show considerably lower High Risk proportions. This indicates smoking is a strong amplifying factor regardless of gender and should be a primary target for prevention campaigns.

Sheet High-Risk Cohort Analysis
A1: 4️⃣ Build a cohort segmentation: Age > 50, Diabetes = Yes, Hypertension Stage 1/2. What % of this cohort is classified as High CVD Risk?
A3: Why:
A4: Comorbidities compound cardiovascular risk.
A6: Purpose:
A7: Identifies ultra-high-risk population segments for intervention.
A11: Row Labels | B11: Sum of High Risk Patients (1 or 0) | C11: Count of Sex | D11: % of high risk patients
A12: High Risk Flag | B12: 120 | C12: 209 | D12: =B12*100/C12 -> 57.416268
A13: Low Risk Flag | B13: 608 | C13: 1320 | D13: =B13*100/C13 -> 46.060606
A14: Grand Total | B14: 728 | C14: 1529 | D14: 100
A18: Among patients belonging to the cohort (Age > 50, Diabetes = Yes, Hypertension Stage 1/2), 57.42% are classified as High CVD Risk. This percentage is higher than the non-cohort group (46.06%), confirming that combined comorbidities substantially increase cardiovascular risk. This cohort represents a critical target population for intensive preventive interventions.

Sheet BMI & CVD Risk Analysis
A1: 5️⃣ Create BMI Categories (Underweight, Normal, Overweight, Obese). Calculate risk distribution and average risk score per category. Does obesity strongly correlate with risk score?
A3: Why:
A4: Obesity is a primary modifiable CVD driver.
A6: Purpose:
A7: Supports obesity reduction initiatives.
B10: Column Labels
B11: HIGH | D11: INTERMEDIARY | F11: LOW | H11: Total Average of CVD Risk Score | I11: Total Count of Sex
A12: Row Labels | B12: Average of CVD Risk Score | C12: Count of Sex | D12: Average of CVD Risk Score | E12: Count of Sex | F12: Average of CVD Risk Score | G12: Count of Sex
A13: Obese | B13: 18.715446 | C13: 360 | D13: 17.673204 | E13: 192 | F13: 18.816 | G13: 83 | H13: 18.418232 | I13: 635
A14: Overweight | B14: 16.95854 | C14: 160 | D14: 16.396877 | E14: 112 | F14: 17.330619 | G14: 46 | H14: 16.811195 | I14: 318
A15: Normal Weight | B15: 16.069049 | C15: 151 | D15: 15.145349 | E15: 191 | F15: 15.441819 | G15: 76 | H15: 15.526628 | I15: 418
A16: Underweight | B16: 16.257906 | C16: 57 | D16: 14.705128 | E16: 86 | F16: 14.045385 | G16: 15 | H16: 15.190132 | I16: 158
A17: Grand Total | B17: 17.611323 | C17: 728 | D17: 16.133444 | E17: 581 | F17: 17.006419 | G17: 220 | H17: 16.960925 | I17: 1529
A23: Obese patients show the highest average CVD Risk Score (18.42), followed by overweight, normal, and underweight groups, indicating a clear upward trend in risk with increasing BMI. The correlation coefficient (r = 0.61) suggests a moderate-to-strong positive relationship between BMI and cardiovascular risk. This indicates that obesity is a significant contributing factor and should be a primary focus of preventive healthcare strategies.
A26: correlation between bmi and cvd risk score
A27: =CORREL('CVD Dataset'!E:E,'CVD Dataset'!AE:AE) -> 0.61644658

Sheet Central Obesity vs. LDL Trend
A1: 6️⃣ Create Waist-to-Height Ratio quartiles (Q1–Q4) and compare average LDL and Risk Score across quartiles. Does central obesity outperform BMI in predicting risk?
A3: Why:
A4: Central fat distribution may be more predictive than overall weight.
A6: Purpose:
A7: Improves screening accuracy.
A11: Row Labels | B11: Average of Estimated LDL (mg/dL) | C11: Average of CVD Risk Score
A12: Q1 | B12: 112.22753 | C12: 16.722582
A13: Q2 | B13: 106.87647 | C13: 16.759859
A14: Q3 | B14: 109.7017 | C14: 16.961971
A15: Q4 | B15: 117.86607 | C15: 17.473312 | E15: BMI vs CVD Risk Score
A16: Grand Total | B16: 111.63945 | C16: 16.976918 | E16: =CORREL('CVD Dataset'!E:E,'CVD Dataset'!AE:AE) -> 0.61644658
E18: Waist-to-Height Ratio vs CVD Risk Score
A19: Patients in the highest Waist-to-Height Ratio quartile (Q4) show the highest average LDL (117.87 mg/dL) and CVD Risk Score (17.47), indicating that central obesity is strongly associated with cardiovascular risk. The upward trend from Q1 to Q4 suggests a dose-response relationship. If correlation strength exceeds that of BMI (r = 0.61), central obesity may be a stronger predictor of cardiovascular risk and should be emphasized in screening protocols. | E19: =CORREL('CVD Dataset'!W:W, 'CVD Dataset'!AE:AE) -> 0.11509024

Sheet Waist vs. BMI Risk Audit
A1: 7️⃣ Compare correlation of Abdominal Circumference and BMI with CVD Risk Score using Excel CORREL. Which is stronger?
A3: Why:
A4: Some obesity measures may be redundant.
A6: Purpose:
A7: Supports feature selection for modeling.
B11: Abdominal Circumference vs CVD Risk Score
B12: =CORREL('CVD Dataset'!I:I,'CVD Dataset'!AE:AE) -> 0.086472366
B15: BMI vs CVD Risk Score
B16: =CORREL('CVD Dataset'!E:E,'CVD Dataset'!AE:AE) -> 0.61644658
B20: BMI demonstrates a moderate-to-strong positive correlation with CVD Risk Score (r = 0.62), whereas Abdominal Circumference shows a negligible relationship (r ≈ 0.09). This suggests BMI is a significantly stronger linear predictor of cardiovascular risk in this dataset. From a feature selection perspective, BMI provides more predictive value, while Abdominal Circumference may be redundant if included alongside BMI.

Sheet Hidden Risk Factor Analysis
A1: 8️⃣ Identify patients with Normal BMI but High Risk Level. What hidden factors (cholesterol, diabetes, BP) explain this?
A3: Why:
A4: Not all high-risk patients are overweight.
A6: Purpose:
A7: Prevents missed diagnoses.
A9: CVD Risk Level | B9: HIGH
A11: Row Labels | B11: Average of Total Cholesterol (mg/dL) | C11: Total Patients | D11: Total High Risk Patient | E11: Average of CVD Risk Score | F11: Average of Fasting Blood Sugar (mg/dL)
A12: Normal Weight | B12: 207.81944 | C12: 151 | D12: 151 | E12: 16.069049 | F12: 121.02759
A13: Obese | B13: 207.31412 | C13: 360 | D13: 360 | E13: 18.715446 | F13: 116.28736
A14: Overweight | B14: 208.31126 | C14: 160 | D14: 160 | E14: 16.95854 | F14: 115.77483
A15: Underweight | B15: 219.16981 | C15: 57 | D15: 57 | E15: 16.257906 | F15: 115.70909
A16: Grand Total | B16: 208.53957 | C16: 728 | D16: 728 | E16: 17.611323 | F16: 117.11445
A19: Among patients with Normal BMI, 151 individuals are classified as High Risk. Despite normal weight, this subgroup shows elevated fasting blood sugar (~121 mg/dL), borderline high systolic blood pressure (~127 mmHg), and increased cholesterol (~208 mg/dL). This indicates that metabolic factors — rather than obesity alone — are driving cardiovascular risk in this population. Therefore, relying solely on BMI as a screening tool may lead to under-identification of high-risk individuals.

Sheet BP Category & Risk Pivot
A1: 9️⃣ Create BP Category vs Risk Level pivot. What % of Hypertension Stage 2 patients fall into High Risk?
A3: Why:
A4: Severe hypertension should strongly predict risk.
A6: Purpose:
A7: Supports aggressive BP control policies.
A12: Count of Sex | B12: Column Labels
A13: Blood Pressure Category | B13: High Risk Patients | C13: Not High Risk Patients | D13: Grand Total
A14: Elevated | B14: 0.52 | C14: 0.48 | D14: 1
A15: Hypertension Stage 1 | B15: 0.50704225 | C15: 0.49295775 | D15: 1
A16: Hypertension Stage 2 | B16: 0.4414557 | C16: 0.5585443 | D16: 1
A17: Normal | B17: 0.48333333 | C17: 0.51666667 | D17: 1
A18: Grand Total | B18: 0.47612819 | C18: 0.52387181 | D18: 1
A22: 44.15% of patients with Hypertension Stage 2 are classified as High Risk. Surprisingly, this proportion is slightly lower than Stage 1 (50.70%) and Elevated BP (52.00%). This suggests that while blood pressure contributes to risk, other clinical factors (such as diabetes, cholesterol, or age) may have stronger influence in the overall risk classification.

Sheet BP Severity vs. Risk Score
A1: 🔟 Calculate average Risk Score for Normal, Elevated, Stage 1, and Stage 2 BP. Is risk score linearly increasing with severity?
A3: Why:
A4: Risk may escalate non-linearly.
A6: Purpose:
A7: Refines clinical escalation guidelines.
A11: Row Labels | B11: Average of CVD Risk Score
A12: Elevated | B12: 17.213542
A13: Hypertension Stage 1 | B13: 16.88974
A14: Hypertension Stage 2 | B14: 17.56386
A15: Normal | B15: 15.7046
A16: Grand Total | B16: 16.960925
A20: The average CVD Risk Score generally increases with BP severity, from 15.70 (Normal) to 17.56 (Stage 2). However, the progression is not perfectly linear, as Stage 1 (16.89) shows a slightly lower average risk score than Elevated BP (17.21). This suggests that while blood pressure severity contributes to risk escalation, other clinical factors may influence overall risk classification.

Sheet LDL-Driven Risk (Normal BP)
A1: 1️⃣1️⃣ Identify patients with Normal BP, High LDL, and High Risk. What % of total high-risk patients fall into this group?
A3: Why:
A4: Some risk is lipid-driven rather than BP-driven.
A6: Purpose:
A7: Improves lipid-focused intervention planning.
A10: Row Labels | B10: Sum of High Risk Patients (1 or 0)
A11: High Lipid Category | B11: 0.11401099
A12: Normal Category | B12: 0.88598901
A13: Grand Total | B13: 1
A16: Approximately 11.4% of all High Risk patients exhibit Normal Blood Pressure but elevated LDL levels, indicating a lipid-driven risk profile independent of hypertension. While this subgroup is smaller relative to the total high-risk population, it represents a clinically important segment that may benefit from targeted lipid-lowering interventions.

Sheet SBP vs. Risk Score Scatter
A2: 1️⃣2️⃣ Build a scatter analysis (Systolic BP vs Risk Score). Is the relationship linear or clustered?
A4: Why:
A5: Understanding pattern helps predictive modeling.
A7: Purpose:
A8: Supports regression model development.
B12: Correlation Between Systolic BP and Risk Score
B13: =CORREL('CVD Dataset'!K:K,'CVD Dataset'!AE:AE) -> 0.48420794
B17: The scatter plot shows a moderate positive linear relationship between Systolic BP and CVD Risk Score (r = 0.48). Risk score generally increases as systolic BP increases, though the dispersion of points suggests additional factors also influence risk. The relationship appears approximately linear rather than clustered, supporting the suitability of linear regression modeling.

Sheet Cholesterol-Risk Distribution
A1: 1️⃣3️⃣ Segment Total Cholesterol into <150, 150–180, >180. How does Risk Score behave across these groups?
A3: Why:
A4: Cholesterol is a primary atherosclerosis driver.
A6: Purpose:
A7: Strengthens lipid control programs.
A11: Cholestrol Category | B11: Average of CVD Risk Score
A12: >180 | B12: 17.883832
A13: 150-180 | B13: 16.162185
A14: <150 | B14: 15.615627
A15: Grand Total | B15: 16.960925
A19: Average CVD Risk Score increases consistently across cholesterol categories, from 15.62 in the <150 mg/dL group to 17.88 in the >180 mg/dL group. This indicates a clear dose-response relationship between total cholesterol levels and cardiovascular risk, supporting cholesterol as a strong risk-stratifying factor.

Sheet Ratio vs. LDL Risk Analysis
A1: 1️⃣4️⃣ Create LDL/HDL ratio column. Does LDL/HDL ratio predict High Risk better than LDL alone?
A3: Why:
A4: Ratio may better represent lipid imbalance.
A6: Purpose:
A7: Improves predictive risk scoring models.
A9: LDL/HDL ratio VS CVD high Risk
A10: =CORREL('CVD Dataset'!AE:AE,'CVD Dataset'!AC:AC) -> 0.32024272
A12: LDL VS CVD high risk
A13: =CORREL('CVD Dataset'!AB:AB,'CVD Dataset'!AE:AE) -> 0.48484242
A16: The LDL/HDL ratio shows a weaker association with High CVD Risk (r = 0.32) compared to LDL alone (r = 0.48). This indicates that, within this dataset, absolute LDL levels provide stronger discriminatory power for identifying high-risk patients than the LDL/HDL ratio. From a feature selection perspective, LDL alone would be preferred over LDL/HDL ratio due to higher explanatory strength and reduced redundancy.

Sheet Diabetic vs. Non-Diabetic Audit
A1: 1️⃣5️⃣ Compare diabetic vs non-diabetic patients on Avg Fasting Blood Sugar and Avg Risk Score. What is incremental risk due to diabetes?
A3: Why:
A4: Diabetes accelerates vascular damage.
A6: Purpose:
A7: Supports integrated diabetes-cardiology programs.
A12: Diabetes | B12: Average of Fasting Blood Sugar (mg/dL) | C12: Average of CVD Risk Score
A13: Non-Diabetic | B13: 117.13783 | C13: 15.84809
A14: Diabetic | B14: 117.81491 | C14: 18.051111
A15: Grand Total | B15: 117.48564 | C15: 16.960925
A19: Diabetic patients exhibit a significantly higher average CVD Risk Score (18.05) compared to non-diabetic patients (15.85), representing an incremental risk increase of approximately +2.2 points. Interestingly, average fasting blood sugar levels are similar between the two groups, suggesting that diabetes status captures broader metabolic and vascular risk beyond a single glucose measurement. This highlights diabetes as a strong independent risk amplifier for cardiovascular disease.

Sheet High HDL |  High Risk Audit
A1: 1️⃣6️⃣ Identify High HDL but High Risk patients. What other variables are driving their risk?
A3: Why:
A4: Good cholesterol alone may not offset other factors.
A6: Purpose:
A7: Improves multi-factor risk understanding. | D7: Patients with High HDL but High CVD Risk exhibit higher BMI (~30.4), elevated systolic blood pressure (~126.5 mmHg), and borderline LDL levels (~113 mg/dL) compared to the overall population. Despite protective HDL levels, the presence of obesity, hypertension, and metabolic risk factors offsets HDL’s protective effect, resulting in elevated cardiovascular risk. This highlights that HDL alone is insufficient to counteract cumulative cardiometabolic risk, reinforcing the need for multi-factor risk assessment.
A14: High HDL + High Risk Flag | B14: 1
A16: Average of Age | B16: Average of BMI | C16: Average of Systolic BP (Upper limit) | D16: Average of Diastolic BP (lower limit) | E16: Average of Estimated LDL (mg/dL) | F16: Average of Fasting Blood Sugar (mg/dL)
A17: 48.397541 | B17: 30.414291 | C17: 126.51331 | D17: 82.475285 | E17: 113.4 | F17: 118.08627
A21: Average of Age | B21: Average of BMI | C21: Average of Systolic BP (Upper limit) | D21: Average of Diastolic BP (lower limit) | E21: Average of Estimated LDL (mg/dL) | F21: Average of Fasting Blood Sugar (mg/dL)
A22: 47.0255 | B22: 28.465997 | C22: 125.50229 | D22: 82.956181 | E22: 111.55068 | F22: 117.48564

Sheet Lifestyle Risk Index Analysis
A1: 1️⃣7️⃣ Create a combined lifestyle risk index (Smoking, Diabetes, Low Physical Activity, Family History = 1 point each). Does Risk Score increase as index increases?
A3: Why:
A4: Lifestyle risks accumulate.
A6: Purpose:
A7: Quantifies behavioral risk burden.
A10: Lifestyle Risk Index | B10: Average of CVD Risk Score
A11: 0 | B11: 15.914167
A12: 1 | B12: 16.345448
A13: 2 | B13: 17.135686
A14: 3 | B14: 17.760659
A15: 4 | B15: 17.863355
A16: Grand Total | B16: 16.960925
A19: Correlation between Lifestyle Risk Index and Risk Score
A20: =CORREL('CVD Dataset'!U:U,'CVD Dataset'!AE:AE) -> 0.24706132
A22: The average CVD Risk Score increases consistently as the Lifestyle Risk Index rises from 0 to 4, indicating a cumulative effect of adverse lifestyle factors on cardiovascular risk. Although the correlation between the index and risk score is modest (r ≈ 0.25), the monotonic upward trend confirms that lifestyle risks additively contribute to overall cardiovascular risk. This suggests lifestyle factors act as important amplifiers rather than sole drivers of risk.

Sheet Activity Level & Risk Analysis
A1: 1️⃣8️⃣ Analyze Physical Activity Level vs Average Risk Score. Is there visible protective effect?
A3: Why:
A4: Sedentary lifestyle increases CVD probability.
A6: Purpose:
A7: Supports preventive health campaigns.
A11: Physical Activity | B11: Average of CVD Risk Score
A12: Moderate | B12: 16.990745
A13: Low | B13: 16.952489
A14: High | B14: 16.94015
A15: Grand Total | B15: 16.960925
A18: The average CVD Risk Score shows only marginal differences across physical activity levels, with High activity associated with a slightly lower risk score. However, the differences are minimal, indicating that physical activity alone does not exhibit a strong standalone protective effect in this dataset. This suggests that physical activity likely acts as a secondary modifier of cardiovascular risk and must be evaluated in combination with other metabolic and clinical factors.

Sheet Smoking Risk by Age Cohort
A1: 1️⃣9️⃣ Segment smokers by age groups. Does smoking amplify risk more in older patients?
A3: Why:
A4: Smoking damage compounds with age.
A6: Purpose:
A7: Improves age-specific anti-smoking interventions.
A9: Smoking Status | B9: Y
A11: Count of Sex | B11: Smoking_Status
A12: Age Group | B12: HIGH | C12: INTERMEDIARY | D12: LOW | E12: Grand Total
A13: 25-34 | B13: 0.52597403 | C13: 0.31818182 | D13: 0.15584416 | E13: 1
A14: 35-44 | B14: 0.51470588 | C14: 0.42156863 | D14: 0.06372549 | E14: 1
A15: 45-54 | B15: 0.75268817 | C15: 0.15591398 | D15: 0.091397849 | E15: 1
A16: 55-64 | B16: 0.59310345 | C16: 0.26206897 | D16: 0.14482759 | E16: 1
A17: 65-74 | B17: 0.43589744 | C17: 0.28205128 | D17: 0.28205128 | E17: 1
A18: 75-84 | B18: 0.1 | C18: 0.4 | D18: 0.5 | E18: 1
A19: Grand Total | B19: 0.57620321 | C19: 0.29545455 | D19: 0.12834225 | E19: 1
A21: Among smokers, cardiovascular risk peaks in the 45–54 age group, where over 75% are classified as High Risk. While smoking elevates risk across all ages, its amplification effect is strongest in middle age rather than in the oldest cohorts, possibly due to survivor bias in later years.

Sheet BMI Validation Audit
A1: 2️⃣0️⃣Validate BMI calculation using Weight / (Height in meters²). How many mismatches exist?
A3: Why:
A4: Data accuracy affects clinical decisions.
A6: Purpose:
A7: Performs dataset audit and quality control.
A9: Total BMI mismatches to Calculated BMI
A10: 598
A13: Using recalculated BMI from weight and height in meters² and applying a tolerance-based validation (±0.1), 598 records show a true mismatch between stored BMI and calculated BMI. This indicates potential data quality issues such as unit inconsistencies or incorrect BMI derivation, warranting further data cleansing.

Sheet Metric Correlation Matrix
A2: 2️⃣1️⃣Create correlation matrix for BMI, Waist-to-Height Ratio, and Abdominal Circumference. Which predictor is redundant?
A4: Why:
A5: Multicollinearity weakens predictive models.
A7: Purpose:
A8: Improves ML model efficiency. | I8: Waist-to-Height Ratio and Abdominal Circumference are redundant predictors due to very high correlation (~0.90). In a predictive model, one of them should be removed to avoid multicollinearity. Waist-to-Height Ratio is preferable because it is normalized for height and generalizes better across populations.
A12: BMI VS Waist-to-Height Ratio
A13: =CORREL('CVD Dataset'!E:E,'CVD Dataset'!W:W) -> 0.096285843
A16: Waist-to-Height Ratio VS Abdominal Circumference
A17: =CORREL('CVD Dataset'!W:W,'CVD Dataset'!I:I) -> 0.90277512
A20: BMI VS Abdominal Circumference
A21: =CORREL('CVD Dataset'!E:E,'CVD Dataset'!I:I) -> 0.031422487

Sheet CVD Dataset
A1: Sex | B1: Age | C1: Weight (kg) | D1: Height (m) | E1: BMI | F1: Calculated BMI | G1: is BMI same to Calculated BMI | H1: BMI Category | I1: Abdominal Circumference (cm) | J1: Blood Pressure (mmHg) | K1: Systolic BP (Upper limit) | L1: Diastolic BP (lower limit) | M1: Total Cholesterol (mg/dL) | N1: Total Cholesterol Category | O1: HDL (mg/dL) | P1: Fasting Blood Sugar (mg/dL) | Q1: Smoking Status | R1: Diabetes Status | S1: Physical Activity Level | T1: Family History of CVD | U1: lifestyle risk index | V1: Height (cm) | W1: Waist-to-Height Ratio | X1: Waist-to-Height Ratio Quartiles | Y1: Systolic BP | Z1: Diastolic BP | AA1: Blood Pressure Category | AB1: Estimated LDL (mg/dL) | AC1: LDL/HDL | AD1: Lipid Focused Category | AE1: CVD Risk Score | AF1: CVD Risk Level | AG1: High HDL + High Risk Flag | AH1: High Risk Patients | AI1: High Risk Patients (1 or 0) | AJ1: High_Risk_Cohort_Flag
A2: F | B2: 32 | C2: 69.1 | D2: 1.71 | E2: 23.6 | F2: =IFERROR(C2/POWER(D2,2),"") -> 23.631203 | G2: =IF(ABS(E2 - F2) <= 0.1, 0, 1) -> 0 | H2: Normal Weight | I2: 86.2 | J2: 125/79 | K2: 125 | L2: 79 | M2: 248 | N2: >180 | O2: 78 | P2: 111 | Q2: N | R2: Y | S2: Low | T2: N | U2: =SUM(IF(Q2="Y",1,0),IF(R2="Y",1,0),IF(S2="Low",1,0),IF(T2="Y",1,0)) -> 2 | V2: 171 | W2: 0.504 | X2: Q2 | Y2: 125 | Z2: 79 | AA2: Elevated | AB2: 140 | AC2: 1.79 | AD2: =IF(AND('CVD Dataset'!AA2="Normal",'CVD Dataset'!AB2>AVERAGE('CVD Dataset'!AB:AB),'CVD Dataset'!AF2="High"),"High Lipid Category","Normal Category") -> Normal Category | AE2: 17.93 | AF2: INTERMEDIARY | AG2: 0 | AH2: Not High Risk Patients | AI2: =IF(AF2="HIGH",1,0) -> 0 | AJ2: Low Risk Flag
A3: F | B3: 55 | C3: 118.7 | D3: 1.69 | E3: 41.6 | F3: =IFERROR(C3/POWER(D3,2),"") -> 41.560169 | G3: =IF(ABS(E3 - F3) <= 0.1, 0, 1) -> 0 | H3: Obese | I3: 82.5 | J3: 139/70 | K3: 139 | L3: 70 | M3: 162 | N3: 150-180 | O3: 50 | P3: 135 | Q3: Y | R3: Y | S3: High | T3: Y | U3: =SUM(IF(Q3="Y",1,0),IF(R3="Y",1,0),IF(S3="Low",1,0),IF(T3="Y",1,0)) -> 3 | V3: 169 | W3: 0.488 | X3: Q2 | Y3: 139 | Z3: 70 | AA3: Hypertension Stage 1 | AB3: 82 | AC3: 1.64 | AD3: =IF(AND('CVD Dataset'!AA3="Normal",'CVD Dataset'!AB3>AVERAGE('CVD Dataset'!AB:AB),'CVD Dataset'!AF3="High"),"High Lipid Category","Normal Category") -> Normal Category | AE3: 20.51 | AF3: HIGH | AG3: 0 | AH3: High Risk Patients | AI3: =IF(AF3="HIGH",1,0) -> 1 | AJ3: High Risk Flag
A4: M | D4: 1.83 | E4: 26.9 | F4: =IFERROR(C4/POWER(D4,2),"") -> 0 | G4: =IF(ABS(E4 - F4) <= 0.1, 0, 1) -> 1 | H4: Overweight | I4: 106.7 | J4: 104/77 | K4: 104 | L4: 77 | M4: 103 | N4: <150 | O4: 73 | P4: 114 | Q4: N | R4: N | S4: High | T4: Y | U4: =SUM(IF(Q4="Y",1,0),IF(R4="Y",1,0),IF(S4="Low",1,0),IF(T4="Y",1,0)) -> 1 | V4: 183 | W4: 0.583 | X4: Q3 | Y4: 104 | Z4: 77 | AA4: Normal | AB4: 0 | AC4: 0 | AD4: =IF(AND('CVD Dataset'!AA4="Normal",'CVD Dataset'!AB4>AVERAGE('CVD Dataset'!AB:AB),'CVD Dataset'!AF4="High"),"High Lipid Category","Normal Category") -> Normal Category | AE4: 12.64 | AF4: INTERMEDIARY | AG4: 0 | AH4: Not High Risk Patients | AI4: =IF(AF4="HIGH",1,0) -> 0 | AJ4: Low Risk Flag
A5: M | B5: 44 | C5: 108.3 | D5: 1.8 | E5: 33.4 | F5: =IFERROR(C5/POWER(D5,2),"") -> 33.425926 | G5: =IF(ABS(E5 - F5) <= 0.1, 0, 1) -> 0 | H5: Obese | I5: 96.6 | J5: 140/83 | K5: 140 | L5: 83 | M5: 134 | N5: <150 | O5: 46 | P5: 91 | Q5: N | R5: N | S5: High | T5: Y | U5: =SUM(IF(Q5="Y",1,0),IF(R5="Y",1,0),IF(S5="Low",1,0),IF(T5="Y",1,0)) -> 1 | W5: 0.537 | X5: Q3 | Y5: 140 | Z5: 83 | AA5: Hypertension Stage 1 | AB5: 58 | AC5: 1.26 | AD5: =IF(AND('CVD Dataset'!AA5="Normal",'CVD Dataset'!AB5>AVERAGE('CVD Dataset'!AB:AB),'CVD Dataset'!AF5="High"),"High Lipid Category","Normal Category") -> Normal Category | AE5: 16.36 | AF5: INTERMEDIARY | AG5: 0 | AH5: Not High Risk Patients | AI5: =IF(AF5="HIGH",1,0) -> 0 | AJ5: Low Risk Flag
A6: F | B6: 32 | C6: 99.5 | D6: 1.86 | E6: 28.8 | F6: =IFERROR(C6/POWER(D6,2),"") -> 28.76055 | G6: =IF(ABS(E6 - F6) <= 0.1, 0, 1) -> 0 | H6: Overweight | I6: 102.7 | J6: 144/83 | K6: 144 | L6: 83 | M6: 146 | N6: <150 | O6: 64 | P6: 141 | Q6: Y | R6: Y | S6: High | T6: N | U6: =SUM(IF(Q6="Y",1,0),IF(R6="Y",1,0),IF(S6="Low",1,0),IF(T6="Y",1,0)) -> 2 | V6: 186 | W6: 0.552 | X6: Q3 | Y6: 144 | Z6: 83 | AA6: Hypertension Stage 1 | AB6: 52 | AC6: 0.81 | AD6: =IF(AND('CVD Dataset'!AA6="Normal",'CVD Dataset'!AB6>AVERAGE('CVD Dataset'!AB:AB),'CVD Dataset'!AF6="High"),"High Lipid Category","Normal Category") -> Normal Category | AE6: 17.88 | AF6: INTERMEDIARY | AG6: 0 | AH6: Not High Risk Patients | AI6: =IF(AF6="HIGH",1,0) -> 0 | AJ6: Low Risk Flag
A7: F | B7: 58 | C7: 117.9 | D7: 1.87 | E7: 33.7 | F7: =IFERROR(C7/POWER(D7,2),"") -> 33.715577 | G7: =IF(ABS(E7 - F7) <= 0.1, 0, 1) -> 0 | H7: Obese | I7: 81.4 | J7: 142/90 | K7: 142 | L7: 90 | M7: 156 | N7: 150-180 | O7: 67 | P7: 82 | Q7: Y | R7: N | S7: Moderate | T7: Y | U7: =SUM(IF(Q7="Y",1,0),IF(R7="Y",1,0),IF(S7="Low",1,0),IF(T7="Y",1,0)) -> 2 | V7: 187 | W7: 0.435 | X7: Q1 | Y7: 142 | Z7: 90 | AA7: Hypertension Stage 2 | AB7: 59 | AC7: 0.88 | AD7: =IF(AND('CVD Dataset'!AA7="Normal",'CVD Dataset'!AB7>AVERAGE('CVD Dataset'!AB:AB),'CVD Dataset'!AF7="High"),"High Lipid Category","Normal Category") -> Normal Category | AE7: 16.96 | AF7: HIGH | AG7: 1 | AH7: High Risk Patients | AI7: =IF(AF7="HIGH",1,0) -> 1 | AJ7: Low Risk Flag
A8: M | B8: 33 | C8: 117.9 | D8: 1.82 | E8: 35.6 | F8: =IFERROR(C8/POWER(D8,2),"") -> 35.593527 | G8: =IF(ABS(E8 - F8) <= 0.1, 0, 1) -> 0 | H8: Obese | I8: 74.8 | J8: 96/63 | K8: 96 | L8: 63 | M8: 184 | N8: >180 | O8: 66 | P8: 87 | Q8: N | R8: Y | S8: Low | T8: N | U8: =SUM(IF(Q8="Y",1,0),IF(R8="Y",1,0),IF(S8="Low",1,0),IF(T8="Y",1,0)) -> 2 | V8: 182 | W8: 0.411 | X8: Q1 | Y8: 96 | Z8: 63 | AA8: Normal | AB8: 88 | AC8: 1.33 | AD8: =IF(AND('CVD Dataset'!AA8="Normal",'CVD Dataset'!AB8>AVERAGE('CVD Dataset'!AB:AB),'CVD Dataset'!AF8="High"),"High Lipid Category","Normal Category") -> Normal Category | AE8: 17.6 | AF8: INTERMEDIARY | AG8: 0 | AH8: Not High Risk Patients | AI8: =IF(AF8="HIGH",1,0) -> 0 | AJ8: Low Risk Flag
A9: M | B9: 55 | C9: 100.1 | D9: 1.74 | E9: 33.1 | F9: =IFERROR(C9/POWER(D9,2),"") -> 33.062492 | G9: =IF(ABS(E9 - F9) <= 0.1, 0, 1) -> 0 | H9: Obese | I9: 96.6 | J9: 115/73 | K9: 115 | L9: 73 | M9: 287 | N9: >180 | O9: 40 | P9: 96 | Q9: Y | R9: N | S9: Moderate | T9: N | U9: =SUM(IF(Q9="Y",1,0),IF(R9="Y",1,0),IF(S9="Low",1,0),IF(T9="Y",1,0)) -> 1 | V9: 174 | W9: 0.555 | X9: Q3 | Y9: 115 | Z9: 73 | AA9: Normal | AB9: 217 | AC9: 5.43 | AD9: =IF(AND('CVD Dataset'!AA9="Normal",'CVD Dataset'!AB9>AVERAGE('CVD Dataset'!AB:AB),'CVD Dataset'!AF9="High"),"High Lipid Category","Normal Category") -> High Lipid Category | AE9: 18.11 | AF9: HIGH | AG9: 0 | AH9: High Risk Patients | AI9: =IF(AF9="HIGH",1,0) -> 1 | AJ9: Low Risk Flag
A10: F | B10: 37 | C10: 110.1 | D10: 1.86 | E10: 31.8 | F10: =IFERROR(C10/POWER(D10,2),"") -> 31.824488 | G10: =IF(ABS(E10 - F10) <= 0.1, 0, 1) -> 0 | H10: Obese | I10: 92.4 | J10: 107/95 | K10: 107 | L10: 95 | M10: 177 | N10: 150-180 | O10: 68 | P10: 70 | Q10: Y | R10: N | S10: High | T10: N | U10: =SUM(IF(Q10="Y",1,0),IF(R10="Y",1,0),IF(S10="Low",1,0),IF(T10="Y",1,0)) -> 1 | V10: 186 | W10: 0.497 | X10: Q2 | Z10: 95 | AA10: Hypertension Stage 2 | AB10: 79 | AC10: 1.16 | AD10: =IF(AND('CVD Dataset'!AA10="Normal",'CVD Dataset'!AB10>AVERAGE('CVD Dataset'!AB:AB),'CVD Dataset'!AF10="High"),"High Lipid Category","Normal Category") -> Normal Category | AE10: 15.25 | AF10: INTERMEDIARY | AG10: 0 | AH10: Not High Risk Patients | AI10: =IF(AF10="HIGH",1,0) -> 0 | AJ10: Low Risk Flag
A11: F | B11: 58 | C11: 97.6 | D11: 1.86 | E11: 28.2 | F11: =IFERROR(C11/POWER(D11,2),"") -> 28.211354 | G11: =IF(ABS(E11 - F11) <= 0.1, 0, 1) -> 0 | H11: Overweight | I11: 74.6 | J11: 133/83 | K11: 133 | L11: 83 | M11: 281 | N11: >180 | O11: 68 | P11: 126 | Q11: N | R11: N | S11: Moderate | T11: N | U11: =SUM(IF(Q11="Y",1,0),IF(R11="Y",1,0),IF(S11="Low",1,0),IF(T11="Y",1,0)) -> 0 | V11: 186 | W11: 0.401 | X11: Q1 | Y11: 133 | Z11: 83 | AA11: Hypertension Stage 1 | AB11: 183 | AC11: 2.69 | AD11: =IF(AND('CVD Dataset'!AA11="Normal",'CVD Dataset'!AB11>AVERAGE('CVD Dataset'!AB:AB),'CVD Dataset'!AF11="High"),"High Lipid Category","Normal Category") -> Normal Category | AE11: 17.91 | AF11: INTERMEDIARY | AG11: 0 | AH11: Not High Risk Patients | AI11: =IF(AF11="HIGH",1,0) -> 0 | AJ11: Low Risk Flag
A12: F | B12: 38 | C12: 75.6 | D12: 1.6 | E12: 29.5 | F12: =IFERROR(C12/POWER(D12,2),"") -> 29.53125 | G12: =IF(ABS(E12 - F12) <= 0.1, 0, 1) -> 0 | H12: Overweight | I12: 72.3 | J12: 129/87 | K12: 129 | L12: 87 | M12: 269 | N12: >180 | O12: 61 | P12: 74 | Q12: Y | R12: Y | S12: Low | T12: Y | U12: =SUM(IF(Q12="Y",1,0),IF(R12="Y",1,0),IF(S12="Low",1,0),IF(T12="Y",1,0)) -> 4 | V12: 160 | W12: 0.452 | X12: Q1 | Y12: 129 | Z12: 87 | AA12: Hypertension Stage 1 | AB12: 178 | AC12: 2.92 | AD12: =IF(AND('CVD Dataset'!AA12="Normal",'CVD Dataset'!AB12>AVERAGE('CVD Dataset'!AB:AB),'CVD Dataset'!AF12="High"),"High Lipid Category","Normal Category") -> Normal Category | AE12: 19.73 | AF12: HIGH | AG12: 1 | AH12: High Risk Patients | AI12: =IF(AF12="HIGH",1,0) -> 1 | AJ12: Low Risk Flag
A13: F | B13: 32 | C13: 90.2 | D13: 1.85 | E13: 26.4 | F13: =IFERROR(C13/POWER(D13,2),"") -> 26.355004 | G13: =IF(ABS(E13 - F13) <= 0.1, 0, 1) -> 0 | H13: Overweight | I13: 71.8 | J13: 134/91 | K13: 134 | L13: 91 | M13: 231 | N13: >180 | O13: 53 | P13: 121 | Q13: N | R13: Y | S13: Moderate | T13: N | U13: =SUM(IF(Q13="Y",1,0),IF(R13="Y",1,0),IF(S13="Low",1,0),IF(T13="Y",1,0)) -> 1 | V13: 185 | W13: 0.388 | X13: Q1 | Y13: 134 | Z13: 91 | AA13: Hypertension Stage 1 | AB13: 148 | AC13: 2.79 | AD13: =IF(AND('CVD Dataset'!AA13="Normal",'CVD Dataset'!AB13>AVERAGE('CVD Dataset'!AB:AB),'CVD Dataset'!AF13="High"),"High Lipid Category","Normal Category") -> Normal Category | AE13: 18.6 | AF13: INTERMEDIARY | AG13: 0 | AH13: Not High Risk Patients | AI13: =IF(AF13="HIGH",1,0) -> 0 | AJ13: Low Risk Flag
A14: M | B14: 48 | E14: 28.8 | F14: =IFERROR(C14/POWER(D14,2),"") | G14: =IFERROR(IF(ABS(E14 - F14) <= 0.1, 0, 1),"") | H14: Overweight | I14: 79.7 | J14: 102/63 | K14: 102 | L14: 63 | M14: 245 | N14: >180 | O14: 72 | P14: 97 | Q14: Y | R14: N | S14: Low | T14: Y | U14: =SUM(IF(Q14="Y",1,0),IF(R14="Y",1,0),IF(S14="Low",1,0),IF(T14="Y",1,0)) -> 3 | V14: 178 | W14: 0.448 | X14: Q1 | Y14: 102 | Z14: 63 | AA14: Normal | AB14: 143 | AC14: 1.99 | AD14: =IF(AND('CVD Dataset'!AA14="Normal",'CVD Dataset'!AB14>AVERAGE('CVD Dataset'!AB:AB),'CVD Dataset'!AF14="High"),"High Lipid Category","Normal Category") -> High Lipid Category | AE14: 15.76 | AF14: HIGH | AG14: 1 | AH14: High Risk Patients | AI14: =IF(AF14="HIGH",1,0) -> 1 | AJ14: Low Risk Flag
A15: M | B15: 38 | C15: 117 | D15: 1.81 | E15: 35.7 | F15: =IFERROR(C15/POWER(D15,2),"") -> 35.713196 | G15: =IFERROR(IF(ABS(E15 - F15) <= 0.1, 0, 1),"") -> 0 | H15: Obese | I15: 79.3 | J15: 142/92 | K15: 142 | L15: 92 | M15: 206 | N15: >180 | O15: 51 | P15: 122 | Q15: Y | R15: Y | S15: High | T15: Y | U15: =SUM(IF(Q15="Y",1,0),IF(R15="Y",1,0),IF(S15="Low",1,0),IF(T15="Y",1,0)) -> 3 | V15: 181 | W15: 0.438 | X15: Q1 | Y15: 142 | Z15: 92 | AA15: Hypertension Stage 2 | AB15: 125 | AC15: 2.45 | AD15: =IF(AND('CVD Dataset'!AA15="Normal",'CVD Dataset'!AB15>AVERAGE('CVD Dataset'!AB:AB),'CVD Dataset'!AF15="High"),"High Lipid Category","Normal Category") -> Normal Category | AE15: 20.36 | AF15: HIGH | AG15: 0 | AH15: High Risk Patients | AI15: =IF(AF15="HIGH",1,0) -> 1 | AJ15: Low Risk Flag
A16: M | B16: 58 | C16: 104.2 | D16: 1.73 | E16: 34.8 | F16: =IFERROR(C16/POWER(D16,2),"") -> 34.815731 | G16: =IFERROR(IF(ABS(E16 - F16) <= 0.1, 0, 1),"") -> 0 | H16: Obese | I16: 108.4 | J16: 101/64 | K16: 101 | L16: 64 | N16: <150 | O16: 68 | P16: 142 | Q16: Y | R16: Y | S16: Low | T16: Y | U16: =SUM(IF(Q16="Y",1,0),IF(R16="Y",1,0),IF(S16="Low",1,0),IF(T16="Y",1,0)) -> 4 | V16: 173 | W16: 0.627 | X16: Q4 | Y16: 101 | Z16: 64 | AA16: Normal | AB16: 190 | AC16: 2.79 | AD16: =IF(AND('CVD Dataset'!AA16="Normal",'CVD Dataset'!AB16>AVERAGE('CVD Dataset'!AB:AB),'CVD Dataset'!AF16="High"),"High Lipid Category","Normal Category") -> High Lipid Category | AF16: HIGH | AG16: 1 | AH16: High Risk Patients | AI16: =IF(AF16="HIGH",1,0) -> 1 | AJ16: Low Risk Flag
A17: M | B17: 38 | C17: 116.5 | D17: 1.64 | E17: 43.3 | F17: =IFERROR(C17/POWER(D17,2),"") -> 43.314991 | G17: =IFERROR(IF(ABS(E17 - F17) <= 0.1, 0, 1),"") -> 0 | H17: Obese | I17: 76.7 | J17: 101/67 | K17: 101 | L17: 67 | M17: 115 | N17: <150 | O17: 41 | P17: 111 | Q17: N | R17: N | S17: Low | T17: N | U17: =SUM(IF(Q17="Y",1,0),IF(R17="Y",1,0),IF(S17="Low",1,0),IF(T17="Y",1,0)) -> 1 | V17: 164 | W17: 0.468 | X17: Q2 | Y17: 101 | Z17: 67 | AA17: Normal | AB17: 44 | AC17: 1.07 | AD17: =IF(AND('CVD Dataset'!AA17="Normal",'CVD Dataset'!AB17>AVERAGE('CVD Dataset'!AB:AB),'CVD Dataset'!AF17="High"),"High Lipid Category","Normal Category") -> Normal Category | AE17: 16.01 | AF17: INTERMEDIARY | AG17: 0 | AH17: Not High Risk Patients | AI17: =IF(AF17="HIGH",1,0) -> 0 | AJ17: Low Risk Flag
A18: F | B18: 41 | C18: 60.8 | D18: 1.68 | E18: 21.5 | F18: =IFERROR(C18/POWER(D18,2),"") -> 21.54195 | G18: =IFERROR(IF(ABS(E18 - F18) <= 0.1, 0, 1),"") -> 0 | H18: Normal Weight | I18: 77.1 | J18: 138/99 | K18: 138 | L18: 99 | N18: <150 | O18: 60 | Q18: Y | R18: Y | S18: Low | T18: N | U18: =SUM(IF(Q18="Y",1,0),IF(R18="Y",1,0),IF(S18="Low",1,0),IF(T18="Y",1,0)) -> 3 | V18: 168 | Y18: 138 | Z18: 99 | AA18: Hypertension Stage 1 | AB18: 138 | AC18: 2.3 | AD18: =IF(AND('CVD Dataset'!AA18="Normal",'CVD Dataset'!AB18>AVERAGE('CVD Dataset'!AB:AB),'CVD Dataset'!AF18="High"),"High Lipid Category","Normal Category") -> Normal Category | AE18: 17.76 | AF18: HIGH | AG18: 1 | AH18: High Risk Patients | AI18: =IF(AF18="HIGH",1,0) -> 1 | AJ18: Low Risk Flag
A19: M | B19: 57 | C19: 94.5 | D19: 1.8 | E19: 29.2 | F19: =IFERROR(C19/POWER(D19,2),"") -> 29.166667 | G19: =IFERROR(IF(ABS(E19 - F19) <= 0.1, 0, 1),"") -> 0 | H19: Overweight | I19: 89.9 | J19: 129/100 | K19: 129 | L19: 100 | N19: <150 | O19: 64 | P19: 109 | Q19: N | R19: Y | S19: Moderate | T19: N | U19: =SUM(IF(Q19="Y",1,0),IF(R19="Y",1,0),IF(S19="Low",1,0),IF(T19="Y",1,0)) -> 1 | V19: 180 | W19: 0.499 | X19: Q2 | Y19: 129 | Z19: 100 | AA19: Hypertension Stage 2 | AB19: 78 | AC19: 1.22 | AD19: =IF(AND('CVD Dataset'!AA19="Normal",'CVD Dataset'!AB19>AVERAGE('CVD Dataset'!AB:AB),'CVD Dataset'!AF19="High"),"High Lipid Category","Normal Category") -> Normal Category | AE19: 17.73 | AF19: INTERMEDIARY | AG19: 0 | AH19: Not High Risk Patients | AI19: =IF(AF19="HIGH",1,0) -> 0 | AJ19: High Risk Flag
A20: F | B20: 41 | C20: 58.3 | D20: 1.85 | E20: 17 | F20: =IFERROR(C20/POWER(D20,2),"") -> 17.034332 | G20: =IFERROR(IF(ABS(E20 - F20) <= 0.1, 0, 1),"") -> 0 | H20: Underweight | I20: 100.6 | J20: 138/96 | K20: 138 | L20: 96 | M20: 167 | N20: 150-180 | O20: 51 | P20: 135 | Q20: N | R20: N | S20: Moderate | T20: Y | U20: =SUM(IF(Q20="Y",1,0),IF(R20="Y",1,0),IF(S20="Low",1,0),IF(T20="Y",1,0)) -> 1 | V20: 185 | Y20: 138 | Z20: 96 | AA20: Hypertension Stage 1 | AB20: 86 | AC20: 1.69 | AD20: =IF(AND('CVD Dataset'!AA20="Normal",'CVD Dataset'!AB20>AVERAGE('CVD Dataset'!AB:AB),'CVD Dataset'!AF20="High"),"High Lipid Category","Normal Category") -> Normal Category | AE20: 13.64 | AF20: LOW | AG20: 0 | AH20: Not High Risk Patients | AI20: =IF(AF20="HIGH",1,0) -> 0 | AJ20: Low Risk Flag
A21: F | B21: 48 | C21: 50.6 | D21: 1.7 | E21: 17.5 | F21: =IFERROR(C21/POWER(D21,2),"") -> 17.508651 | G21: =IFERROR(IF(ABS(E21 - F21) <= 0.1, 0, 1),"") -> 0 | H21: Underweight | J21: 95/92 | K21: 95 | L21: 92 | M21: 185 | N21: >180 | O21: 68 | P21: 116 | Q21: Y | R21: N | S21: Low | T21: Y | U21: =SUM(IF(Q21="Y",1,0),IF(R21="Y",1,0),IF(S21="Low",1,0),IF(T21="Y",1,0)) -> 3 | V21: 170 | W21: 0.646 | X21: Q4 | Y21: 95 | Z21: 92 | AA21: Hypertension Stage 2 | AB21: 87 | AC21: 1.28 | AD21: =IF(AND('CVD Dataset'!AA21="Normal",'CVD Dataset'!AB21>AVERAGE('CVD Dataset'!AB:AB),'CVD Dataset'!AF21="High"),"High Lipid Category","Normal Category") -> Normal Category | AE21: 11.95 | AF21: HIGH | AG21: 1 | AH21: High Risk Patients | AI21: =IF(AF21="HIGH",1,0) -> 1 | AJ21: Low Risk Flag
A22: F | B22: 40 | C22: 85.6 | D22: 1.77 | E22: 27.3 | F22: =IFERROR(C22/POWER(D22,2),"") -> 27.322928 | G22: =IFERROR(IF(ABS(E22 - F22) <= 0.1, 0, 1),"") -> 0 | H22: Overweight | I22: 98.7 | J22: 132/92 | K22: 132 | L22: 92 | M22: 282 | N22: >180 | O22: 80 | P22: 112 | Q22: Y | R22: Y | S22: Low | T22: Y | U22: =SUM(IF(Q22="Y",1,0),IF(R22="Y",1,0),IF(S22="Low",1,0),IF(T22="Y",1,0)) -> 4 | V22: 177 | W22: 0.558 | X22: Q3 | Y22: 132 | Z22: 92 | AA22: Hypertension Stage 1 | AB22: 172 | AC22: 2.15 | AD22: =IF(AND('CVD Dataset'!AA22="Normal",'CVD Dataset'!AB22>AVERAGE('CVD Dataset'!AB:AB),'CVD Dataset'!AF22="High"),"High Lipid Category","Normal Category") -> Normal Category | AE22: 19.7 | AF22: HIGH | AG22: 1 | AH22: High Risk Patients | AI22: =IF(AF22="HIGH",1,0) -> 1 | AJ22: Low Risk Flag
A23: F | B23: 39 | C23: 92.7 | D23: 1.61 | E23: 35.8 | F23: =IFERROR(C23/POWER(D23,2),"") -> 35.762509 | G23: =IFERROR(IF(ABS(E23 - F23) <= 0.1, 0, 1),"") -> 0 | H23: Obese | I23: 105.6 | J23: 120/89 | K23: 120 | L23: 89 | M23: 176 | N23: 150-180 | O23: 71 | P23: 85 | Q23: Y | R23: N | S23: Low | T23: Y | U23: =SUM(IF(Q23="Y",1,0),IF(R23="Y",1,0),IF(S23="Low",1,0),IF(T23="Y",1,0)) -> 3 | V23: 161 | W23: 0.656 | X23: Q4 | Y23: 120 | Z23: 89 | AA23: Hypertension Stage 1 | AB23: 75 | AC23: 1.06 | AD23: =IF(AND('CVD Dataset'!AA23="Normal",'CVD Dataset'!AB23>AVERAGE('CVD Dataset'!AB:AB),'CVD Dataset'!AF23="High"),"High Lipid Category","Normal Category") -> Normal Category | AE23: 16.68 | AF23: HIGH | AG23: 1 | AH23: High Risk Patients | AI23: =IF(AF23="HIGH",1,0) -> 1 | AJ23: Low Risk Flag
A24: F | B24: 34 | C24: 90.4 | E24: 25 | F24: =IFERROR(C24/POWER(D24,2),"") | G24: =IFERROR(IF(ABS(E24 - F24) <= 0.1, 0, 1),"") | H24: Overweight | I24: 71.4 | J24: 121/79 | K24: 121 | L24: 79 | M24: 149 | N24: <150 | O24: 76 | P24: 114 | Q24: N | R24: Y | S24: Low | T24: Y | U24: =SUM(IF(Q24="Y",1,0),IF(R24="Y",1,0),IF(S24="Low",1,0),IF(T24="Y",1,0)) -> 3 | V24: 190 | W24: 0.376 | X24: Q1 | AA24: Elevated | AB24: 43 | AC24: 0.57 | AD24: =IF(AND('CVD Dataset'!AA24="Normal",'CVD Dataset'!AB24>AVERAGE('CVD Dataset'!AB:AB),'CVD Dataset'!AF24="High"),"High Lipid Category","Normal Category") -> Normal Category | AE24: 16.03 | AF24: HIGH | AG24: 1 | AH24: High Risk Patients | AI24: =IF(AF24="HIGH",1,0) -> 1 | AJ24: Low Risk Flag
A25: F | B25: 35 | C25: 60.1 | D25: 1.76 | E25: 19.4 | F25: =IFERROR(C25/POWER(D25,2),"") -> 19.402118 | G25: =IFERROR(IF(ABS(E25 - F25) <= 0.1, 0, 1),"") -> 0 | H25: Normal Weight | I25: 86.9 | J25: 102/74 | K25: 102 | L25: 74 | M25: 191 | N25: >180 | O25: 65 | P25: 86 | Q25: N | R25: N | S25: Moderate | T25: Y | U25: =SUM(IF(Q25="Y",1,0),IF(R25="Y",1,0),IF(S25="Low",1,0),IF(T25="Y",1,0)) -> 1 | V25: 176 | W25: 0.494 | X25: Q2 | Y25: 102 | Z25: 74 | AA25: Normal | AB25: 96 | AC25: 1.48 | AD25: =IF(AND('CVD Dataset'!AA25="Normal",'CVD Dataset'!AB25>AVERAGE('CVD Dataset'!AB:AB),'CVD Dataset'!AF25="High"),"High Lipid Category","Normal Category") -> Normal Category | AE25: 12.8 | AF25: LOW | AG25: 0 | AH25: Not High Risk Patients | AI25: =IF(AF25="HIGH",1,0) -> 0 | AJ25: Low Risk Flag
A26: M | B26: 36 | C26: 96 | D26: 1.63 | E26: 36.1 | F26: =IFERROR(C26/POWER(D26,2),"") -> 36.132335 | G26: =IFERROR(IF(ABS(E26 - F26) <= 0.1, 0, 1),"") -> 0 | H26: Obese | I26: 78.2 | J26: 98/99 | K26: 98 | L26: 99 | M26: 158 | N26: 150-180 | O26: 39 | P26: 108 | Q26: Y | R26: Y | S26: Low | T26: Y | U26: =SUM(IF(Q26="Y",1,0),IF(R26="Y",1,0),IF(S26="Low",1,0),IF(T26="Y",1,0)) -> 4 | V26: 163 | W26: 0.48 | X26: Q2 | Y26: 98 | Z26: 99 | AA26: Hypertension Stage 2 | AB26: 89 | AC26: 2.28 | AD26: =IF(AND('CVD Dataset'!AA26="Normal",'CVD Dataset'!AB26>AVERAGE('CVD Dataset'!AB:AB),'CVD Dataset'!AF26="High"),"High Lipid Category","Normal Category") -> Normal Category | AE26: 17.28 | AF26: HIGH | AG26: 0 | AH26: High Risk Patients | AI26: =IF(AF26="HIGH",1,0) -> 1 | AJ26: Low Risk Flag
A27: F | B27: 53 | C27: 68.9 | D27: 1.88 | E27: 19.5 | F27: =IFERROR(C27/POWER(D27,2),"") -> 19.494115 | G27: =IFERROR(IF(ABS(E27 - F27) <= 0.1, 0, 1),"") -> 0 | H27: Normal Weight | I27: 84.6 | J27: 137/70 | K27: 137 | L27: 70 | M27: 156 | N27: 150-180 | P27: 128 | Q27: Y | R27: Y | S27: High | T27: Y | U27: =SUM(IF(Q27="Y",1,0),IF(R27="Y",1,0),IF(S27="Low",1,0),IF(T27="Y",1,0)) -> 3 | V27: 188 | W27: 0.45 | X27: Q1 | Y27: 137 | Z27: 70 | AA27: Hypertension Stage 1 | AB27: 47 | AD27: =IF(AND('CVD Dataset'!AA27="Normal",'CVD Dataset'!AB27>AVERAGE('CVD Dataset'!AB:AB),'CVD Dataset'!AF27="High"),"High Lipid Category","Normal Category") -> Normal Category | AE27: 15.87 | AF27: HIGH | AG27: 0 | AH27: High Risk Patients | AI27: =IF(AF27="HIGH",1,0) -> 1 | AJ27: High Risk Flag
A28: F | B28: 55 | C28: 96 | D28: 1.65 | E28: 35.3 | F28: =IFERROR(C28/POWER(D28,2),"") -> 35.261708 | G28: =IFERROR(IF(ABS(E28 - F28) <= 0.1, 0, 1),"") -> 0 | H28: Obese | I28: 83.6 | J28: 148/97 | K28: 148 | L28: 97 | M28: 160 | N28: 150-180 | O28: 41 | Q28: N | R28: N | S28: Low | T28: Y | U28: =SUM(IF(Q28="Y",1,0),IF(R28="Y",1,0),IF(S28="Low",1,0),IF(T28="Y",1,0)) -> 2 | V28: 165 | W28: 0.507 | X28: Q2 | Y28: 148 | AA28: Hypertension Stage 2 | AB28: 89 | AC28: 2.17 | AD28: =IF(AND('CVD Dataset'!AA28="Normal",'CVD Dataset'!AB28>AVERAGE('CVD Dataset'!AB:AB),'CVD Dataset'!AF28="High"),"High Lipid Category","Normal Category") -> Normal Category | AE28: 17.66 | AF28: HIGH | AG28: 0 | AH28: High Risk Patients | AI28: =IF(AF28="HIGH",1,0) -> 1 | AJ28: Low Risk Flag
A29: M | B29: 47 | C29: 111.6 | D29: 1.73 | F29: =IFERROR(C29/POWER(D29,2),"") -> 37.288249 | G29: =IFERROR(IF(ABS(E29 - F29) <= 0.1, 0, 1),"") -> 1 | H29: Underweight | I29: 75.9 | J29: 128/66 | K29: 128 | L29: 66 | M29: 283 | N29: >180 | O29: 64 | P29: 142 | Q29: Y | R29: N | S29: Low | T29: N | U29: =SUM(IF(Q29="Y",1,0),IF(R29="Y",1,0),IF(S29="Low",1,0),IF(T29="Y",1,0)) -> 2 | V29: 173 | W29: 0.439 | X29: Q1 | Y29: 128 | Z29: 66 | AA29: Elevated | AB29: 189 | AC29: 2.95 | AD29: =IF(AND('CVD Dataset'!AA29="Normal",'CVD Dataset'!AB29>AVERAGE('CVD Dataset'!AB:AB),'CVD Dataset'!AF29="High"),"High Lipid Category","Normal Category") -> Normal Category | AE29: 19.52 | AF29: HIGH | AG29: 1 | AH29: High Risk Patients | AI29: =IF(AF29="HIGH",1,0) -> 1 | AJ29: Low Risk Flag
A30: M | B30: 55 | C30: 106 | D30: 1.82 | E30: 32 | F30: =IFERROR(C30/POWER(D30,2),"") -> 32.000966 | G30: =IFERROR(IF(ABS(E30 - F30) <= 0.1, 0, 1),"") -> 0 | H30: Obese | I30: 109.3 | J30: 97/63 | K30: 97 | L30: 63 | M30: 287 | N30: >180 | O30: 35 | P30: 130 | Q30: N | R30: Y | S30: Moderate | T30: N | U30: =SUM(IF(Q30="Y",1,0),IF(R30="Y",1,0),IF(S30="Low",1,0),IF(T30="Y",1,0)) -> 1 | V30: 182 | W30: 0.601 | X30: Q4 | Y30: 97 | Z30: 63 | AA30: Normal | AB30: 222 | AC30: 6.34 | AD30: =IF(AND('CVD Dataset'!AA30="Normal",'CVD Dataset'!AB30>AVERAGE('CVD Dataset'!AB:AB),'CVD Dataset'!AF30="High"),"High Lipid Category","Normal Category") -> High Lipid Category | AE30: 18.99 | AF30: HIGH | AG30: 0 | AH30: High Risk Patients | AI30: =IF(AF30="HIGH",1,0) -> 1 | AJ30: Low Risk Flag
A31: M | B31: 30 | D31: 1.83 | E31: 22.6 | F31: =IFERROR(C31/POWER(D31,2),"") -> 0 | G31: =IFERROR(IF(ABS(E31 - F31) <= 0.1, 0, 1),"") -> 1 | H31: Normal Weight | I31: 75.1 | J31: 91/95 | K31: 91 | L31: 95 | M31: 277 | N31: >180 | O31: 32 | P31: 73 | Q31: Y | R31: N | S31: Moderate | T31: Y | U31: =SUM(IF(Q31="Y",1,0),IF(R31="Y",1,0),IF(S31="Low",1,0),IF(T31="Y",1,0)) -> 2 | V31: 183 | W31: 0.41 | X31: Q1 | Y31: 91 | Z31: 95 | AA31: Hypertension Stage 2 | AB31: 215 | AC31: 6.72 | AD31: =IF(AND('CVD Dataset'!AA31="Normal",'CVD Dataset'!AB31>AVERAGE('CVD Dataset'!AB:AB),'CVD Dataset'!AF31="High"),"High Lipid Category","Normal Category") -> Normal Category | AE31: 14.61 | AF31: HIGH | AG31: 0 | AH31: High Risk Patients | AI31: =IF(AF31="HIGH",1,0) -> 1 | AJ31: Low Risk Flag
A32: F | B32: 58 | C32: 64.7 | D32: 1.64 | E32: 24.1 | F32: =IFERROR(C32/POWER(D32,2),"") -> 24.055622 | G32: =IFERROR(IF(ABS(E32 - F32) <= 0.1, 0, 1),"") -> 0 | H32: Normal Weight | I32: 82.1 | J32: 97/75 | K32: 97 | L32: 75 | M32: 151 | N32: 150-180 | O32: 40 | P32: 123 | Q32: Y | R32: N | S32: Low | T32: N | U32: =SUM(IF(Q32="Y",1,0),IF(R32="Y",1,0),IF(S32="Low",1,0),IF(T32="Y",1,0)) -> 2 | V32: 164 | Y32: 97 | Z32: 75 | AA32: Normal | AB32: 81 | AC32: 2.03 | AD32: =IF(AND('CVD Dataset'!AA32="Normal",'CVD Dataset'!AB32>AVERAGE('CVD Dataset'!AB:AB),'CVD Dataset'!AF32="High"),"High Lipid Category","Normal Category") -> Normal Category | AE32: 12.69 | AF32: INTERMEDIARY | AG32: 0 | AH32: Not High Risk Patients | AI32: =IF(AF32="HIGH",1,0) -> 0 | AJ32: Low Risk Flag
A33: F | B33: 31 | C33: 51.6 | D33: 1.71 | E33: 17.6 | F33: =IFERROR(C33/POWER(D33,2),"") -> 17.646455 | G33: =IFERROR(IF(ABS(E33 - F33) <= 0.1, 0, 1),"") -> 0 | H33: Underweight | I33: 93.7 | J33: 109/64 | K33: 109 | L33: 64 | M33: 165 | N33: 150-180 | O33: 79 | P33: 136 | Q33: Y | R33: Y | S33: Low | T33: N | U33: =SUM(IF(Q33="Y",1,0),IF(R33="Y",1,0),IF(S33="Low",1,0),IF(T33="Y",1,0)) -> 3 | V33: 171 | W33: 0.548 | X33: Q3 | Y33: 109 | Z33: 64 | AA33: Normal | AB33: 56 | AC33: 0.71 | AD33: =IF(AND('CVD Dataset'!AA33="Normal",'CVD Dataset'!AB33>AVERAGE('CVD Dataset'!AB:AB),'CVD Dataset'!AF33="High"),"High Lipid Category","Normal Category") -> Normal Category | AE33: 14.27 | AF33: INTERMEDIARY | AG33: 0 | AH33: Not High Risk Patients | AI33: =IF(AF33="HIGH",1,0) -> 0 | AJ33: Low Risk Flag
A34: M | B34: 55 | C34: 112.8 | D34: 1.74 | E34: 37.3 | F34: =IFERROR(C34/POWER(D34,2),"") -> 37.257233 | G34: =IFERROR(IF(ABS(E34 - F34) <= 0.1, 0, 1),"") -> 0 | H34: Obese | I34: 80.9 | J34: 106/87 | K34: 106 | L34: 87 | M34: 145 | N34: <150 | O34: 32 | P34: 150 | Q34: Y | R34: Y | S34: High | T34: Y | U34: =SUM(IF(Q34="Y",1,0),IF(R34="Y",1,0),IF(S34="Low",1,0),IF(T34="Y",1,0)) -> 3 | V34: 174 | W34: 0.465 | X34: Q2 | Y34: 106 | Z34: 87 | AA34: Hypertension Stage 1 | AB34: 83 | AC34: 2.59 | AD34: =IF(AND('CVD Dataset'!AA34="Normal",'CVD Dataset'!AB34>AVERAGE('CVD Dataset'!AB:AB),'CVD Dataset'!AF34="High"),"High Lipid Category","Normal Category") -> Normal Category | AE34: 17.66 | AF34: HIGH | AG34: 0 | AH34: High Risk Patients | AI34: =IF(AF34="HIGH",1,0) -> 1 | AJ34: High Risk Flag
A35: M | B35: 37 | C35: 108.4 | E35: 36.2 | F35: =IFERROR(C35/POWER(D35,2),"") | G35: =IFERROR(IF(ABS(E35 - F35) <= 0.1, 0, 1),"") | H35: Obese | I35: 80.1 | J35: 100/83 | K35: 100 | L35: 83 | N35: <150 | O35: 48 | P35: 145 | Q35: Y | R35: N | S35: Moderate | T35: N | U35: =SUM(IF(Q35="Y",1,0),IF(R35="Y",1,0),IF(S35="Low",1,0),IF(T35="Y",1,0)) -> 1 | V35: 173 | W35: 0.463 | X35: Q2 | Y35: 100 | Z35: 83 | AA35: Hypertension Stage 1 | AB35: 55 | AC35: 1.15 | AD35: =IF(AND('CVD Dataset'!AA35="Normal",'CVD Dataset'!AB35>AVERAGE('CVD Dataset'!AB:AB),'CVD Dataset'!AF35="High"),"High Lipid Category","Normal Category") -> Normal Category | AE35: 14.9 | AF35: INTERMEDIARY | AG35: 0 | AH35: Not High Risk Patients | AI35: =IF(AF35="HIGH",1,0) -> 0 | AJ35: Low Risk Flag
A36: M | B36: 32 | D36: 1.62 | E36: 24 | F36: =IFERROR(C36/POWER(D36,2),"") -> 0 | G36: =IFERROR(IF(ABS(E36 - F36) <= 0.1, 0, 1),"") -> 1 | H36: Normal Weight | I36: 105.5 | J36: 122/84 | K36: 122 | L36: 84 | M36: 155 | N36: 150-180 | O36: 74 | P36: 130 | Q36: N | R36: N | S36: Low | T36: N | U36: =SUM(IF(Q36="Y",1,0),IF(R36="Y",1,0),IF(S36="Low",1,0),IF(T36="Y",1,0)) -> 1 | V36: 162 | W36: 0.651 | X36: Q4 | Y36: 122 | Z36: 84 | AA36: Hypertension Stage 1 | AB36: 51 | AC36: 0.69 | AD36: =IF(AND('CVD Dataset'!AA36="Normal",'CVD Dataset'!AB36>AVERAGE('CVD Dataset'!AB:AB),'CVD Dataset'!AF36="High"),"High Lipid Category","Normal Category") -> Normal Category | AE36: 14 | AF36: LOW | AG36: 0 | AH36: Not High Risk Patients | AI36: =IF(AF36="HIGH",1,0) -> 0 | AJ36: Low Risk Flag
A37: M | B37: 45 | C37: 58.7 | D37: 1.73 | E37: 19.6 | F37: =IFERROR(C37/POWER(D37,2),"") -> 19.613084 | G37: =IFERROR(IF(ABS(E37 - F37) <= 0.1, 0, 1),"") -> 0 | H37: Normal Weight | J37: 136/80 | K37: 136 | L37: 80 | M37: 286 | N37: >180 | O37: 73 | P37: 141 | Q37: N | R37: Y | S37: High | T37: Y | U37: =SUM(IF(Q37="Y",1,0),IF(R37="Y",1,0),IF(S37="Low",1,0),IF(T37="Y",1,0)) -> 2 | V37: 173 | W37: 0.46 | X37: Q1 | Y37: 136 | AA37: Hypertension Stage 1 | AB37: 183 | AC37: 2.51 | AD37: =IF(AND('CVD Dataset'!AA37="Normal",'CVD Dataset'!AB37>AVERAGE('CVD Dataset'!AB:AB),'CVD Dataset'!AF37="High"),"High Lipid Category","Normal Category") -> Normal Category | AE37: 18.44 | AF37: INTERMEDIARY | AG37: 0 | AH37: Not High Risk Patients | AI37: =IF(AF37="HIGH",1,0) -> 0 | AJ37: Low Risk Flag
A38: F | B38: 32 | C38: 116.2 | E38: 36.7 | F38: =IFERROR(C38/POWER(D38,2),"") | G38: =IFERROR(IF(ABS(E38 - F38) <= 0.1, 0, 1),"") | H38: Obese | I38: 89.8 | J38: 99/99 | K38: 99 | L38: 99 | M38: 115 | N38: <150 | O38: 52 | P38: 147 | Q38: N | R38: Y | S38: Moderate | T38: Y | U38: =SUM(IF(Q38="Y",1,0),IF(R38="Y",1,0),IF(S38="Low",1,0),IF(T38="Y",1,0)) -> 2 | V38: 178 | W38: 0.504 | X38: Q2 | Y38: 99 | Z38: 99 | AA38: Hypertension Stage 2 | AB38: 33 | AC38: 0.63 | AD38: =IF(AND('CVD Dataset'!AA38="Normal",'CVD Dataset'!AB38>AVERAGE('CVD Dataset'!AB:AB),'CVD Dataset'!AF38="High"),"High Lipid Category","Normal Category") -> Normal Category | AE38: 16.59 | AF38: INTERMEDIARY | AG38: 0 | AH38: Not High Risk Patients | AI38: =IF(AF38="HIGH",1,0) -> 0 | AJ38: Low Risk Flag
A39: F | B39: 42 | C39: 100.4 | D39: 1.77 | E39: 32 | F39: =IFERROR(C39/POWER(D39,2),"") -> 32.046985 | G39: =IFERROR(IF(ABS(E39 - F39) <= 0.1, 0, 1),"") -> 0 | H39: Obese | I39: 82.5 | J39: 144/73 | K39: 144 | L39: 73 | M39: 164 | N39: 150-180 | O39: 75 | P39: 96 | Q39: N | R39: Y | S39: High | T39: Y | U39: =SUM(IF(Q39="Y",1,0),IF(R39="Y",1,0),IF(S39="Low",1,0),IF(T39="Y",1,0)) -> 2 | V39: 177 | W39: 0.466 | X39: Q2 | Y39: 144 | Z39: 73 | AA39: Hypertension Stage 2 | AB39: 59 | AC39: 0.79 | AD39: =IF(AND('CVD Dataset'!AA39="Normal",'CVD Dataset'!AB39>AVERAGE('CVD Dataset'!AB:AB),'CVD Dataset'!AF39="High"),"High Lipid Category","Normal Category") -> Normal Category | AE39: 18.88 | AF39: INTERMEDIARY | AG39: 0 | AH39: Not High Risk Patients | AI39: =IF(AF39="HIGH",1,0) -> 0 | AJ39: Low Risk Flag
A40: M | B40: 33 | C40: 81.6 | D40: 1.87 | E40: 23.3 | F40: =IFERROR(C40/POWER(D40,2),"") -> 23.334954 | G40: =IFERROR(IF(ABS(E40 - F40) <= 0.1, 0, 1),"") -> 0 | H40: Normal Weight | I40: 70 | J40: 130/75 | K40: 130 | L40: 75 | M40: 285 | N40: >180 | O40: 69 | Q40: N | R40: N | S40: Low | T40: N | U40: =SUM(IF(Q40="Y",1,0),IF(R40="Y",1,0),IF(S40="Low",1,0),IF(T40="Y",1,0)) -> 1 | V40: 187 | W40: 0.374 | X40: Q1 | Z40: 75 | AA40: Hypertension Stage 1 | AB40: 186 | AC40: 2.7 | AD40: =IF(AND('CVD Dataset'!AA40="Normal",'CVD Dataset'!AB40>AVERAGE('CVD Dataset'!AB:AB),'CVD Dataset'!AF40="High"),"High Lipid Category","Normal Category") -> Normal Category | AE40: 16.86 | AF40: INTERMEDIARY | AG40: 0 | AH40: Not High Risk Patients | AI40: =IF(AF40="HIGH",1,0) -> 0 | AJ40: Low Risk Flag
...

Sheet Questions
A1: ❤️ Cardiovascular Disease Risk — Excel Data Analysis Questions (30)
A3: (Dataset: CVD Dataset.csv — Bangladesh, 2024–2025)
A7: 🧬 Demographic & Risk Exposure Analysis
A9: 1️⃣ Create an age-band classification (25–35, 36–45, 46–55, 56–65, 66+) and calculate % of High Risk patients and Average CVD Risk Score per band. Which age group shows the highest risk concentration?
A11: Why this question is asked:
A12: Cardiovascular risk increases with age but not always uniformly.
A14: Business purpose:
A15: Helps hospitals design age-targeted screening and preventive strategies.
A19: 2️⃣ Perform gender-based risk comparison: Average CVD Risk Score by Sex and % High Risk by Sex. Is risk significantly different between males and females?
A21: Why:
A22: Risk profiles differ biologically and behaviorally.
A24: Purpose:
... A225: Improves ML model efficiency.
